<?xml version="1.0"?>
<robot name="gokart" xmlns:xacro="http://ros.org/wiki/xacro">

  <!-- ****************** ROBOT CONSTANTS *******************************  -->
  <!-- Define the size of the robot's main chassis in meters -->
  <xacro:property name="base_width" value="0.39" />
  <xacro:property name="base_length" value="0.70" />
  <xacro:property name="base_height" value="0.20" />

  <!-- Define the shape of the robot's two back wheels in meters -->
  <xacro:property name="wheel_radius" value="0.14" />
  <xacro:property name="wheel_width" value="0.06" />

  <!-- x-axis points forward, y-axis points to left, z-axis points upwards -->
  <!-- Define the gap between the wheel and chassis along y-axis in meters -->
  <xacro:property name="wheel_ygap" value="0.035" />

  <!-- Position the wheels along the z-axis -->
  <xacro:property name="wheel_zoff" value="0.05" />

  <!-- Position the wheels along the x-axis -->
  <xacro:property name="wheel_xoff" value="0.221" />

  <!-- Position the caster wheel along the x-axis -->
  <xacro:property name="caster_xoff" value="0.217" />

  <!-- Define intertial property macros  -->
  <xacro:macro name="box_inertia" params="m w h d">
    <inertial>
      <origin xyz="0 0 0" rpy="${pi/2} 0 ${pi/2}" />
      <mass value="${m}" />
      <inertia ixx="${(m/12) * (h*h + d*d)}" ixy="0.0" ixz="0.0" iyy="${(m/12) * (w*w + d*d)}" iyz="0.0" izz="${(m/12) * (w*w + h*h)}" />
    </inertial>
  </xacro:macro>

  <xacro:macro name="cylinder_inertia" params="m r h">
    <inertial>
      <origin xyz="0 0 0" rpy="${pi/2} 0 0" />
      <mass value="${m}" />
      <inertia ixx="${(m/12) * (3*r*r + h*h)}" ixy="0" ixz="0" iyy="${(m/12) * (3*r*r + h*h)}" iyz="0" izz="${(m/2) * (r*r)}" />
    </inertial>
  </xacro:macro>

  <xacro:macro name="sphere_inertia" params="m r">
    <inertial>
      <mass value="${m}" />
      <inertia ixx="${(2/5) * m * (r*r)}" ixy="0.0" ixz="0.0" iyy="${(2/5) * m * (r*r)}" iyz="0.0" izz="${(2/5) * m * (r*r)}" />
    </inertial>
  </xacro:macro>

  <link name="root_link"></link>

  <joint name="root_joint" type="fixed">
    <parent link="root_link" />
    <child link="base_link" />
    <origin xyz="0.0 0.0 0.0" rpy="0 0 0" />
  </joint>

  <!-- ********************** ROBOT BASE *********************************  -->
  <link name="base_link">
    <visual>
      <origin xyz="0 0 -0.05" rpy="1.5707963267949 0 3.141592654" />
      <geometry>
        <mesh filename="file://$(find simulator)/meshes/robot_base.stl" />
      </geometry>
      <material name="Red">
        <color rgba="1.0 0.0 0.0 1.0" />
      </material>
    </visual>

    <collision>
      <geometry>
        <box size="${base_length} ${base_width} ${base_height}" />
      </geometry>
    </collision>

    <xacro:box_inertia m="15.0" w="${base_width}" d="${base_length}" h="${base_height}" />
  </link>

  <gazebo reference="base_link">
    <material>Gazebo/Red</material>
  </gazebo>


  <!-- ****************** ROBOT BASE FOOTPRINT ***************************  -->
  <!-- Define the center of the main robot chassis projected on the ground -->
  <link name="base_footprint">
    <xacro:box_inertia m="0" w="0" d="0" h="0" />
  </link>

  <!-- The base footprint of the robot is located underneath the chassis -->
  <joint name="base_joint" type="fixed">
    <parent link="base_link" />
    <child link="base_footprint" />
    <origin xyz="0.0 0.0 ${-(wheel_radius+wheel_zoff)}" rpy="0 0 0" />
  </joint>

  <!-- *********************** DRIVE WHEELS ******************************  -->
  <xacro:macro name="wheel" params="prefix x_reflect y_reflect">
    <link name="${prefix}_link">
      <visual>
        <origin xyz="0 0 0" rpy="${pi/2} 0 0" />
        <geometry>
          <cylinder radius="${wheel_radius}" length="${wheel_width}" />
        </geometry>
        <material name="Gray">
          <color rgba="0.5 0.5 0.5 1.0" />
        </material>
      </visual>

      <collision>
        <origin xyz="0 0 0" rpy="${pi/2} 0 0" />
        <geometry>
          <cylinder radius="${wheel_radius}" length="${wheel_width}" />
        </geometry>
      </collision>

      <xacro:cylinder_inertia m="0.5" r="${wheel_radius}" h="${wheel_width}" />
    </link>

    <!-- Connect the wheels to the base_link at the appropriate location, and 
         define a continuous joint to allow the wheels to freely rotate about
         an axis -->
    <joint name="${prefix}_joint" type="continuous">
      <parent link="base_link" />
      <child link="${prefix}_link" />
      <origin xyz="${x_reflect*wheel_xoff} ${y_reflect*(base_width/2+wheel_ygap)} ${-wheel_zoff}" rpy="0 0 0" />
      <axis xyz="0 1 0" />
    </joint>
  </xacro:macro>

  <!-- *********************** STEER WHEELS ******************************  -->
  <xacro:macro name="steer_wheel" params="prefix x_reflect y_reflect side">

    <!-- Steer hinge -->
    <link name="${prefix}_steer_link">

      <xacro:cylinder_inertia m="0.1" r="${wheel_radius}" h="${wheel_width}" />
    </link>

    <!-- Connect the steer_link to the base_link at the appropriate location, and 
         define a continuous joint to allow the wheels to freely rotate about
         an axis -->
    <joint name="${prefix}_steer_joint" type="continuous">
      <parent link="base_link" />
      <child link="${prefix}_steer_link" />
      <origin xyz="${x_reflect*wheel_xoff} ${y_reflect*(base_width/2+wheel_ygap)} ${-wheel_zoff}" rpy="0 0 0" />
      <axis xyz="0 0 1" />
    </joint>

    <!-- Wheel -->
    <link name="${prefix}_link">
      <visual>
        <origin xyz="0 0 0" rpy="${pi/2} 0 0" />
        <geometry>
          <cylinder radius="${wheel_radius}" length="${wheel_width}" />
        </geometry>
        <material name="Gray">
          <color rgba="0.5 0.5 0.5 1.0" />
        </material>
      </visual>

      <collision>
        <origin xyz="0 0 0" rpy="${pi/2} 0 0" />
        <geometry>
          <cylinder radius="${wheel_radius}" length="${wheel_width}" />
        </geometry>
      </collision>

      <xacro:cylinder_inertia m="0.5" r="${wheel_radius}" h="${wheel_width}" />
    </link>

    <!-- Connect the wheels to the steer_link at the appropriate location, and 
         define a continuous joint to allow the wheels to freely rotate about
         an axis -->
    <joint name="${prefix}_joint" type="continuous">
      <parent link="${prefix}_steer_link" />
      <child link="${prefix}_link" />
      <origin xyz="0 ${side*0.02} 0" rpy="0 0 0" />
      <axis xyz="0 1 0" />
    </joint>
  </xacro:macro>

  <!-- Instantiate two wheels using the macro we just made through the 
       xacro:wheel tags. We also define the parameters to have one wheel
       on both sides at the back of our robot (i.e. x_reflect=-1). -->
  <xacro:wheel prefix="drivewhl_l" x_reflect="-1" y_reflect="1.2" />
  <xacro:wheel prefix="drivewhl_r" x_reflect="-1" y_reflect="-1.2" />

  <xacro:steer_wheel prefix="drivewhl_fl" x_reflect="1" y_reflect="1.2" side="1" />
  <xacro:steer_wheel prefix="drivewhl_fr" x_reflect="1" y_reflect="-1.2"  side="-1" />

  <!-- plugins -->

  <gazebo>
      <plugin name="simulator_gazebo_plugin" filename="libsimulator_gazebo_plugin.so">
      </plugin>
  </gazebo>

</robot>